Workbook

Sheet Read me
A1: Global F&B City: game economy
A2: Draft v0.3: every Restaurant City system is included, with what the original did shown beside our settings.
A4: How to use
A5: Change | B5: Only blue cells. Black and green cells are formulas.
A6: Pale yellow | B6: Our own proposals or changes from Restaurant City.
A7: Pale blue | B7: What Restaurant City did, for reference, or features taken from it.
A8: IDs | B8: Lowercase IDs are what the game code uses. Don't rename an ID once the developer uses it.
A9: Phase 1 | B9: Set Yes or No in each "In Phase 1" column; the Phase 1 scope sheet counts it.
A10: What changed in v0.3
A11: Dish levels | B11: Up to 10, as in Restaurant City (was 5). One full set of ingredients per level; price rises 20% per level.
A12: Menu | B12: Starters, mains and desserts from level 1, drinks from level 15. 1 dish per category, 2 from level 10, 3 from level 20.
A13: New content | B13: 5 drinks, 5 ingredients, toilets, a drinks counter, a jukebox and an arcade machine.
A14: Levels | B14: 65 levels with staff slots (up to 9), garden plots (up to 9) and expansions, including outdoor terraces from level 20.
A15: New settings | B15: Staff energy, snacks and breaks; login streak; daily quiz; visit rewards; gifts; trash; surprise visitor; garden; market; fun machines.
A16: Sell-back | B16: One third of the price, as in Restaurant City (was half).
A17: Sheets
A18: Phase 1 scope | B18: What goes into the vertical slice.
A19: Settings | B19: All global rules, with the Restaurant City reference column.
A20: Ingredients | B20: 38 ingredients with 1 to 5 star rarity.
A21: Dishes | B21: 25 dishes in 4 categories with prices for levels 1 to 10.
A22: Furniture | B22: 38 items with cost, ambience and unlock level.
A23: Expansions | B23: Indoor expansions, outdoor terraces and a second restaurant in another city.
A24: Levels | B24: Levels 1 to 65 and what each unlocks.
A25: Staff | B25: Roles and hire costs.
A26: Balance check | B26: Rough guests and coins per minute.
A27: Known gaps
A28: Premium currency | B28: Gold Spoon prices and the shop are not here yet.
A29: Timers | B29: The crate cooldown is a testing value. Set real timers after playtests.

Sheet Phase 1 scope
A1: Phase 1 scope: vertical slice
A2: Counts update from the Yes/No columns. Blue numbers are targets for content outside this workbook.
A4: Content | B4: Phase 1 amount | C4: Notes
A5: Gameplay content
A6: Dishes | B6: =COUNTIF(Dishes!$Y$5:$Y$29,"Yes") -> 7 | C6: Malaysia's 4, plus pizza, burger and pancakes so starters, mains and desserts are all covered
A7: Ingredients | B7: =COUNTIF(Ingredients!$I$5:$I$42,"Yes") -> 18 | C7: Only what the Phase 1 dishes use
A8: of which grown in the garden | B8: =COUNTIFS(Ingredients!$C$5:$C$42,"Garden",Ingredients!$I$5:$I$42,"Yes") -> 3
A9: Restaurant levels | B9: =Settings!$B$102 -> 10 | C9: Set in Settings
A10: Menu slots at the top Phase 1 level | B10: =INDEX(Levels!$G$5:$G$69,Settings!$B$102) -> 6
A11: Staff slots at the top Phase 1 level | B11: =INDEX(Levels!$H$5:$H$69,Settings!$B$102) -> 5
A12: Garden plots at the top Phase 1 level | B12: =INDEX(Levels!$I$5:$I$69,Settings!$B$102) -> 3
A13: Restaurant expansions | B13: =COUNTIF(Expansions!$H$5:$H$15,"Yes") -> 1
A14: Staff roles | B14: =COUNTIF(Staff!$E$5:$E$7,"Yes") -> 2 | C14: Chef and waiter
A15: Surprise visitor types | B15: 1 | C15: Travelling chef
A16: Daily goal pool | B16: 15 | C16: 3 offered per day
A17: Tutorial length (minutes) | B17: 10
A18: Friend restaurants to visit | B18: 1 | C18: A pretend friend; real friends come in Phase 2
A19: Art
A20: Working furniture | B20: =COUNTIFS(Furniture!$C$5:$C$42,"Function",Furniture!$L$5:$L$42,"Yes") -> 6
A21: Fun machines | B21: =COUNTIFS(Furniture!$C$5:$C$42,"Fun",Furniture!$L$5:$L$42,"Yes") -> 0 | C21: Restaurant City-style machines come at launch
A22: Decor items | B22: =COUNTIFS(Furniture!$C$5:$C$42,"Decor",Furniture!$L$5:$L$42,"Yes") -> 20
A23: of which Malaysia themed set | B23: =COUNTIFS(Furniture!$K$5:$K$42,"Malaysia",Furniture!$L$5:$L$42,"Yes") -> 10
A24: Floors | B24: =COUNTIFS(Furniture!$C$5:$C$42,"Floor",Furniture!$L$5:$L$42,"Yes") -> 4
A25: Wallpapers | B25: =COUNTIFS(Furniture!$C$5:$C$42,"Wallpaper",Furniture!$L$5:$L$42,"Yes") -> 4
A26: Character parts | B26: 30
A27: Character animations | B27: 6
A28: UI icons and buttons | B28: 20
A29: Game screens | B29: 8
A30: Total art pieces | B30: =B20+B21+B22+B24+B25+2*B6+B7+B26+B28 -> 116 | C30: Furniture, floors, walls, 2 per dish, ingredient icons, character parts, UI icons

Sheet Settings
A1: Global tuning settings
A2: Blue values are inputs. The blue-shaded column shows what Restaurant City did, for reference. Our coin amounts use our own scale, not Restaurant City's.
A4: Setting | B4: Value | C4: Unit | D4: Source | E4: Notes | F4: Restaurant City did
A5: Start
A6: Starting coins | B6: 400 | C6: coins | D6: Prototype
A7: Starting star rating | B7: 3 | C7: stars | D7: Prototype | F7: Approval rating from 0 to 50
A8: Starting tables | B8: 4 | C8: tables | D8: Prototype
A9: Starting staff | B9: 2 | C9: people | D9: Prototype | E9: 1 chef and 1 waiter | F9: At least a chef and a waiter
A10: Progression
A11: XP curve: base | B11: 80 | C11: XP | D11: Prototype | E11: XP to next level = base + per level x current level | F11: Levels came from points earned by serving
A12: XP curve: added per level | B12: 60 | C12: XP | D12: Prototype
A13: Highest restaurant level | B13: 65 | C13: level | D13: Restaurant City feature | F13: 65 levels
A14: Coins reward per level-up | B14: 100 | C14: coins | D14: Prototype | F14: 1,000 coins per level, in its own economy
A15: Menu
A16: Menu categories at level 1 | B16: 3 | C16: categories | D16: Restaurant City feature | E16: Starters, mains and desserts | F16: Starters, mains and desserts
A17: Drinks category unlocks at level | B17: 15 | C17: level | D17: Restaurant City feature | E17: Needs a drinks counter | F17: Drinks at level 15
A18: Dishes per category at level 1 | B18: 1 | C18: dishes | D18: Restaurant City feature | F18: One starter, one main, one dessert
A19: 2 dishes per category from level | B19: 10 | C19: level | D19: Restaurant City feature | F19: Level 10
A20: 3 dishes per category from level | B20: 20 | C20: level | D20: Restaurant City feature | F20: Level 20
A21: Dishes
A22: Price increase per dish level | B22: 0.2 | C22: of base price | D22: Changed | E22: Was 35% with 5 levels; 20% keeps level 10 at 2.8x base | F22: Price per serve stayed the same; points per serve rose instead
A23: Max dish level | B23: 10 | C23: level | D23: Restaurant City feature | E23: Was 5 in the prototype | F23: Levels 1 to 10
A24: Ingredients of each type per upgrade | B24: 1 | C24: items | D24: Restaurant City feature | E24: One full set per level; the prototype needed more each level | F24: One full set of the recipe per level
A25: XP per dish served: base | B25: 6 | C25: XP | D25: Prototype | E25: Total = base + per level x dish level
A26: XP per dish served: per dish level | B26: 2 | C26: XP | D26: Prototype | F26: Points per serve rose from 1 to 2.8 with dish level
A27: XP per dish upgrade: base | B27: 20 | C27: XP | D27: Prototype | E27: Total = base + per level x new level
A28: XP per dish upgrade: per level | B28: 10 | C28: XP | D28: New proposal | E28: Bigger rewards for higher levels | F28: 25 points to learn, then 50 rising to 800
A29: Guests
A30: Guest patience: base | B30: 40 | C30: seconds | D30: Prototype
A31: Guest patience: added per ambience point | B31: 1.5 | C31: seconds | D31: Prototype
A32: Eating time | B32: 4 | C32: seconds | D32: Prototype
A33: Tip per ambience point | B33: 0.03 | C33: of bill | D33: Prototype
A34: Tip cap | B34: 0.4 | C34: of bill | D34: Prototype
A35: Guests need toilets from level | B35: 8 | C35: level | D35: Restaurant City feature | F35: Level 8
A36: Arrival interval: base | B36: 9 | C36: seconds | D36: Prototype | E36: Seconds between guests = base - per star x rating - per level x level
A37: Arrival interval: less per star | B37: 1.1 | C37: seconds | D37: Prototype
A38: Arrival interval: less per level | B38: 0.25 | C38: seconds | D38: Prototype
A39: Arrival interval: minimum | B39: 2.2 | C39: seconds | D39: Prototype
A40: Rating
A41: Rating gain: fast service | B41: 0.06 | C41: stars | D41: Prototype | F41: +0.01 per happy guest on a 0 to 50 scale
...

Sheet Ingredients
A1: Ingredients
A2: 38 ingredients for 25 dishes. Rarity runs 1 to 5 stars, as in Restaurant City; rarer items appear less often in random crate slots.
A4: ID | B4: Ingredient | C4: Source | D4: Rarity (stars) | E4: Garden grow time (hours) | F4: Crate weight | G4: Chance per random crate slot | H4: Used in dishes | I4: In Phase 1
A5: rice | B5: Rice | C5: Market | D5: 1 | F5: =MAX(1,12-2*D5) -> 10 | G5: =F5/SUM($F$5:$F$42) -> 0.03164557 | H5: =COUNTIF(Dishes!$E$5:$G$29,A5) -> 4 | I5: =IF(SUMPRODUCT((Dishes!$E$5:$G$29=A5)*(Dishes!$Y$5:$Y$29="Yes"))>0,"Yes","No") -> Yes
A6: coconut | B6: Coconut | C6: Market | D6: 2 | F6: =MAX(1,12-2*D6) -> 8 | G6: =F6/SUM($F$5:$F$42) -> 0.025316456 | H6: =COUNTIF(Dishes!$E$5:$G$29,A6) -> 1 | I6: =IF(SUMPRODUCT((Dishes!$E$5:$G$29=A6)*(Dishes!$Y$5:$Y$29="Yes"))>0,"Yes","No") -> Yes
A7: chili | B7: Chili | C7: Garden | D7: 1 | E7: 24 | F7: =MAX(1,12-2*D7) -> 10 | G7: =F7/SUM($F$5:$F$42) -> 0.03164557 | H7: =COUNTIF(Dishes!$E$5:$G$29,A7) -> 2 | I7: =IF(SUMPRODUCT((Dishes!$E$5:$G$29=A7)*(Dishes!$Y$5:$Y$29="Yes"))>0,"Yes","No") -> Yes
A8: chicken | B8: Chicken | C8: Market | D8: 1 | F8: =MAX(1,12-2*D8) -> 10 | G8: =F8/SUM($F$5:$F$42) -> 0.03164557 | H8: =COUNTIF(Dishes!$E$5:$G$29,A8) -> 2 | I8: =IF(SUMPRODUCT((Dishes!$E$5:$G$29=A8)*(Dishes!$Y$5:$Y$29="Yes"))>0,"Yes","No") -> Yes
A9: peanut | B9: Peanut | C9: Market | D9: 1 | F9: =MAX(1,12-2*D9) -> 10 | G9: =F9/SUM($F$5:$F$42) -> 0.03164557 | H9: =COUNTIF(Dishes!$E$5:$G$29,A9) -> 1 | I9: =IF(SUMPRODUCT((Dishes!$E$5:$G$29=A9)*(Dishes!$Y$5:$Y$29="Yes"))>0,"Yes","No") -> Yes
A10: lemongrass | B10: Lemongrass | C10: Garden | D10: 2 | E10: 36 | F10: =MAX(1,12-2*D10) -> 8 | G10: =F10/SUM($F$5:$F$42) -> 0.025316456 | H10: =COUNTIF(Dishes!$E$5:$G$29,A10) -> 1 | I10: =IF(SUMPRODUCT((Dishes!$E$5:$G$29=A10)*(Dishes!$Y$5:$Y$29="Yes"))>0,"Yes","No") -> Yes
A11: noodles | B11: Noodles | C11: Market | D11: 1 | F11: =MAX(1,12-2*D11) -> 10 | G11: =F11/SUM($F$5:$F$42) -> 0.03164557 | H11: =COUNTIF(Dishes!$E$5:$G$29,A11) -> 2 | I11: =IF(SUMPRODUCT((Dishes!$E$5:$G$29=A11)*(Dishes!$Y$5:$Y$29="Yes"))>0,"Yes","No") -> Yes
A12: shrimp | B12: Shrimp | C12: Market | D12: 3 | F12: =MAX(1,12-2*D12) -> 6 | G12: =F12/SUM($F$5:$F$42) -> 0.018987342 | H12: =COUNTIF(Dishes!$E$5:$G$29,A12) -> 2 | I12: =IF(SUMPRODUCT((Dishes!$E$5:$G$29=A12)*(Dishes!$Y$5:$Y$29="Yes"))>0,"Yes","No") -> Yes
A13: soy_sauce | B13: Soy sauce | C13: Market | D13: 1 | F13: =MAX(1,12-2*D13) -> 10 | G13: =F13/SUM($F$5:$F$42) -> 0.03164557 | H13: =COUNTIF(Dishes!$E$5:$G$29,A13) -> 2 | I13: =IF(SUMPRODUCT((Dishes!$E$5:$G$29=A13)*(Dishes!$Y$5:$Y$29="Yes"))>0,"Yes","No") -> Yes
A14: flour | B14: Flour | C14: Market | D14: 1 | F14: =MAX(1,12-2*D14) -> 10 | G14: =F14/SUM($F$5:$F$42) -> 0.03164557 | H14: =COUNTIF(Dishes!$E$5:$G$29,A14) -> 5 | I14: =IF(SUMPRODUCT((Dishes!$E$5:$G$29=A14)*(Dishes!$Y$5:$Y$29="Yes"))>0,"Yes","No") -> Yes
A15: butter | B15: Butter | C15: Market | D15: 2 | F15: =MAX(1,12-2*D15) -> 8 | G15: =F15/SUM($F$5:$F$42) -> 0.025316456 | H15: =COUNTIF(Dishes!$E$5:$G$29,A15) -> 2 | I15: =IF(SUMPRODUCT((Dishes!$E$5:$G$29=A15)*(Dishes!$Y$5:$Y$29="Yes"))>0,"Yes","No") -> Yes
A16: curry_spice | B16: Curry spice | C16: Market | D16: 2 | F16: =MAX(1,12-2*D16) -> 8 | G16: =F16/SUM($F$5:$F$42) -> 0.025316456 | H16: =COUNTIF(Dishes!$E$5:$G$29,A16) -> 1 | I16: =IF(SUMPRODUCT((Dishes!$E$5:$G$29=A16)*(Dishes!$Y$5:$Y$29="Yes"))>0,"Yes","No") -> Yes
A17: egg | B17: Egg | C17: Market | D17: 1 | F17: =MAX(1,12-2*D17) -> 10 | G17: =F17/SUM($F$5:$F$42) -> 0.03164557 | H17: =COUNTIF(Dishes!$E$5:$G$29,A17) -> 5 | I17: =IF(SUMPRODUCT((Dishes!$E$5:$G$29=A17)*(Dishes!$Y$5:$Y$29="Yes"))>0,"Yes","No") -> Yes
A18: fish | B18: Fish | C18: Market | D18: 3 | F18: =MAX(1,12-2*D18) -> 6 | G18: =F18/SUM($F$5:$F$42) -> 0.018987342 | H18: =COUNTIF(Dishes!$E$5:$G$29,A18) -> 1 | I18: =IF(SUMPRODUCT((Dishes!$E$5:$G$29=A18)*(Dishes!$Y$5:$Y$29="Yes"))>0,"Yes","No") -> No
A19: seaweed | B19: Seaweed | C19: Market | D19: 3 | F19: =MAX(1,12-2*D19) -> 6 | G19: =F19/SUM($F$5:$F$42) -> 0.018987342 | H19: =COUNTIF(Dishes!$E$5:$G$29,A19) -> 1 | I19: =IF(SUMPRODUCT((Dishes!$E$5:$G$29=A19)*(Dishes!$Y$5:$Y$29="Yes"))>0,"Yes","No") -> No
A20: matcha | B20: Matcha | C20: Market | D20: 4 | F20: =MAX(1,12-2*D20) -> 4 | G20: =F20/SUM($F$5:$F$42) -> 0.012658228 | H20: =COUNTIF(Dishes!$E$5:$G$29,A20) -> 2 | I20: =IF(SUMPRODUCT((Dishes!$E$5:$G$29=A20)*(Dishes!$Y$5:$Y$29="Yes"))>0,"Yes","No") -> No
A21: milk | B21: Milk | C21: Market | D21: 1 | F21: =MAX(1,12-2*D21) -> 10 | G21: =F21/SUM($F$5:$F$42) -> 0.03164557 | H21: =COUNTIF(Dishes!$E$5:$G$29,A21) -> 7 | I21: =IF(SUMPRODUCT((Dishes!$E$5:$G$29=A21)*(Dishes!$Y$5:$Y$29="Yes"))>0,"Yes","No") -> Yes
A22: sugar | B22: Sugar | C22: Market | D22: 1 | F22: =MAX(1,12-2*D22) -> 10 | G22: =F22/SUM($F$5:$F$42) -> 0.03164557 | H22: =COUNTIF(Dishes!$E$5:$G$29,A22) -> 6 | I22: =IF(SUMPRODUCT((Dishes!$E$5:$G$29=A22)*(Dishes!$Y$5:$Y$29="Yes"))>0,"Yes","No") -> No
... A24: rice_cake | B24: Rice cake | C24: Market | D24: 3 | F24: =MAX(1,12-2*D24) -> 6 | G24: =F24/SUM($F$5:$F$42) -> 0.018987342 | H24: =COUNTIF(Dishes!$E$5:$G$29,A24) -> 1 | I24: =IF(SUMPRODUCT((Dishes!$E$5:$G$29=A24)*(Dishes!$Y$5:$Y$29="Yes"))>0,"Yes","No") -> No
A25: garlic | B25: Garlic | C25: Garden | D25: 1 | E25: 24 | F25: =MAX(1,12-2*D25) -> 10 | G25: =F25/SUM($F$5:$F$42) -> 0.03164557 | H25: =COUNTIF(Dishes!$E$5:$G$29,A25) -> 1 | I25: =IF(SUMPRODUCT((Dishes!$E$5:$G$29=A25)*(Dishes!$Y$5:$Y$29="Yes"))>0,"Yes","No") -> No
A26: cabbage | B26: Cabbage | C26: Garden | D26: 2 | E26: 48 | F26: =MAX(1,12-2*D26) -> 8 | G26: =F26/SUM($F$5:$F$42) -> 0.025316456 | H26: =COUNTIF(Dishes!$E$5:$G$29,A26) -> 1 | I26: =IF(SUMPRODUCT((Dishes!$E$5:$G$29=A26)*(Dishes!$Y$5:$Y$29="Yes"))>0,"Yes","No") -> No
A27: tofu | B27: Tofu | C27: Market | D27: 2 | F27: =MAX(1,12-2*D27) -> 8 | G27: =F27/SUM($F$5:$F$42) -> 0.025316456 | H27: =COUNTIF(Dishes!$E$5:$G$29,A27) -> 1 | I27: =IF(SUMPRODUCT((Dishes!$E$5:$G$29=A27)*(Dishes!$Y$5:$Y$29="Yes"))>0,"Yes","No") -> No
A28: tomato | B28: Tomato | C28: Garden | D28: 1 | E28: 36 | F28: =MAX(1,12-2*D28) -> 10 | G28: =F28/SUM($F$5:$F$42) -> 0.03164557 | H28: =COUNTIF(Dishes!$E$5:$G$29,A28) -> 1 | I28: =IF(SUMPRODUCT((Dishes!$E$5:$G$29=A28)*(Dishes!$Y$5:$Y$29="Yes"))>0,"Yes","No") -> Yes
A29: cheese | B29: Cheese | C29: Market | D29: 2 | F29: =MAX(1,12-2*D29) -> 8 | G29: =F29/SUM($F$5:$F$42) -> 0.025316456 | H29: =COUNTIF(Dishes!$E$5:$G$29,A29) -> 4 | I29: =IF(SUMPRODUCT((Dishes!$E$5:$G$29=A29)*(Dishes!$Y$5:$Y$29="Yes"))>0,"Yes","No") -> Yes
A30: pasta | B30: Pasta | C30: Market | D30: 1 | F30: =MAX(1,12-2*D30) -> 10 | G30: =F30/SUM($F$5:$F$42) -> 0.03164557 | H30: =COUNTIF(Dishes!$E$5:$G$29,A30) -> 2 | I30: =IF(SUMPRODUCT((Dishes!$E$5:$G$29=A30)*(Dishes!$Y$5:$Y$29="Yes"))>0,"Yes","No") -> No
A31: mushroom | B31: Mushroom | C31: Garden | D31: 3 | E31: 48 | F31: =MAX(1,12-2*D31) -> 6 | G31: =F31/SUM($F$5:$F$42) -> 0.018987342 | H31: =COUNTIF(Dishes!$E$5:$G$29,A31) -> 1 | I31: =IF(SUMPRODUCT((Dishes!$E$5:$G$29=A31)*(Dishes!$Y$5:$Y$29="Yes"))>0,"Yes","No") -> No
A32: coffee | B32: Coffee | C32: Market | D32: 4 | F32: =MAX(1,12-2*D32) -> 4 | G32: =F32/SUM($F$5:$F$42) -> 0.012658228 | H32: =COUNTIF(Dishes!$E$5:$G$29,A32) -> 1 | I32: =IF(SUMPRODUCT((Dishes!$E$5:$G$29=A32)*(Dishes!$Y$5:$Y$29="Yes"))>0,"Yes","No") -> No
A33: cream | B33: Cream | C33: Market | D33: 2 | F33: =MAX(1,12-2*D33) -> 8 | G33: =F33/SUM($F$5:$F$42) -> 0.025316456 | H33: =COUNTIF(Dishes!$E$5:$G$29,A33) -> 1 | I33: =IF(SUMPRODUCT((Dishes!$E$5:$G$29=A33)*(Dishes!$Y$5:$Y$29="Yes"))>0,"Yes","No") -> No
A34: beef | B34: Beef | C34: Market | D34: 2 | F34: =MAX(1,12-2*D34) -> 8 | G34: =F34/SUM($F$5:$F$42) -> 0.025316456 | H34: =COUNTIF(Dishes!$E$5:$G$29,A34) -> 1 | I34: =IF(SUMPRODUCT((Dishes!$E$5:$G$29=A34)*(Dishes!$Y$5:$Y$29="Yes"))>0,"Yes","No") -> Yes
A35: bun | B35: Bun | C35: Market | D35: 1 | F35: =MAX(1,12-2*D35) -> 10 | G35: =F35/SUM($F$5:$F$42) -> 0.03164557 | H35: =COUNTIF(Dishes!$E$5:$G$29,A35) -> 2 | I35: =IF(SUMPRODUCT((Dishes!$E$5:$G$29=A35)*(Dishes!$Y$5:$Y$29="Yes"))>0,"Yes","No") -> Yes
A36: sausage | B36: Chicken sausage | C36: Market | D36: 2 | F36: =MAX(1,12-2*D36) -> 8 | G36: =F36/SUM($F$5:$F$42) -> 0.025316456 | H36: =COUNTIF(Dishes!$E$5:$G$29,A36) -> 1 | I36: =IF(SUMPRODUCT((Dishes!$E$5:$G$29=A36)*(Dishes!$Y$5:$Y$29="Yes"))>0,"Yes","No") -> No
A37: onion | B37: Onion | C37: Garden | D37: 1 | E37: 24 | F37: =MAX(1,12-2*D37) -> 10 | G37: =F37/SUM($F$5:$F$42) -> 0.03164557 | H37: =COUNTIF(Dishes!$E$5:$G$29,A37) -> 1 | I37: =IF(SUMPRODUCT((Dishes!$E$5:$G$29=A37)*(Dishes!$Y$5:$Y$29="Yes"))>0,"Yes","No") -> No
A38: tea | B38: Tea leaves | C38: Garden | D38: 2 | E38: 48 | F38: =MAX(1,12-2*D38) -> 8 | G38: =F38/SUM($F$5:$F$42) -> 0.025316456 | H38: =COUNTIF(Dishes!$E$5:$G$29,A38) -> 1 | I38: =IF(SUMPRODUCT((Dishes!$E$5:$G$29=A38)*(Dishes!$Y$5:$Y$29="Yes"))>0,"Yes","No") -> No
A39: ice | B39: Ice | C39: Market | D39: 1 | F39: =MAX(1,12-2*D39) -> 10 | G39: =F39/SUM($F$5:$F$42) -> 0.03164557 | H39: =COUNTIF(Dishes!$E$5:$G$29,A39) -> 3 | I39: =IF(SUMPRODUCT((Dishes!$E$5:$G$29=A39)*(Dishes!$Y$5:$Y$29="Yes"))>0,"Yes","No") -> No
A40: banana | B40: Banana | C40: Market | D40: 1 | F40: =MAX(1,12-2*D40) -> 10 | G40: =F40/SUM($F$5:$F$42) -> 0.03164557 | H40: =COUNTIF(Dishes!$E$5:$G$29,A40) -> 1 | I40: =IF(SUMPRODUCT((Dishes!$E$5:$G$29=A40)*(Dishes!$Y$5:$Y$29="Yes"))>0,"Yes","No") -> No
A41: lemon | B41: Lemon | C41: Garden | D41: 2 | E41: 36 | F41: =MAX(1,12-2*D41) -> 8 | G41: =F41/SUM($F$5:$F$42) -> 0.025316456 | H41: =COUNTIF(Dishes!$E$5:$G$29,A41) -> 1 | I41: =IF(SUMPRODUCT((Dishes!$E$5:$G$29=A41)*(Dishes!$Y$5:$Y$29="Yes"))>0,"Yes","No") -> No
A42: strawberry | B42: Strawberry | C42: Garden | D42: 3 | E42: 48 | F42: =MAX(1,12-2*D42) -> 6 | G42: =F42/SUM($F$5:$F$42) -> 0.018987342 | H42: =COUNTIF(Dishes!$E$5:$G$29,A42) -> 1 | I42: =IF(SUMPRODUCT((Dishes!$E$5:$G$29=A42)*(Dishes!$Y$5:$Y$29="Yes"))>0,"Yes","No") -> No
...

Sheet Dishes
A1: Dishes
A2: 25 dishes: 4 per cuisine plus a drink each. Drinks unlock at level 15, as in Restaurant City. Level 2 to 10 prices are calculated from Settings.
A4: ID | B4: Dish | C4: Cuisine | D4: Category | E4: Ingredient 1 | F4: Ingredient 2 | G4: Ingredient 3 | H4: Base price (coins) | I4: Cook time (s) | J4: Unlocks at level | K4: Price Lv2 | L4: Price Lv3 | M4: Price Lv4 | N4: Price Lv5 | O4: Price Lv6 | P4: Price Lv7 | Q4: Price Lv8 | R4: Price Lv9 | S4: Price Lv10 | T4: Coins per cook-second (Lv1) | U4: XP per serve (Lv1) | V4: XP per serve (Lv10) | W4: Ingredient check | X4: Notes | Y4: In Phase 1
A5: nasi_lemak | B5: Nasi Lemak | C5: Malaysia | D5: Main | E5: rice | F5: coconut | G5: chili | H5: 12 | I5: 5 | J5: 1 | K5: =ROUND(H5*(1+Settings!$B$22*1),0) -> 14 | L5: =ROUND(H5*(1+Settings!$B$22*2),0) -> 17 | M5: =ROUND(H5*(1+Settings!$B$22*3),0) -> 19 | N5: =ROUND(H5*(1+Settings!$B$22*4),0) -> 22 | O5: =ROUND(H5*(1+Settings!$B$22*5),0) -> 24 | P5: =ROUND(H5*(1+Settings!$B$22*6),0) -> 26 | Q5: =ROUND(H5*(1+Settings!$B$22*7),0) -> 29 | R5: =ROUND(H5*(1+Settings!$B$22*8),0) -> 31 | S5: =ROUND(H5*(1+Settings!$B$22*9),0) -> 34 | T5: =H5/I5 -> 2.4 | U5: =Settings!$B$25+Settings!$B$26*1 -> 8 | V5: =Settings!$B$25+Settings!$B$26*Settings!$B$23 -> 26 | W5: =IF(COUNTIF(Ingredients!$A$5:$A$42,E5)*COUNTIF(Ingredients!$A$5:$A$42,F5)*COUNTIF(Ingredients!$A$5:$A$42,G5)>0,"OK","Missing ingredient") -> OK | X5: Prototype price and cook time | Y5: Yes
A6: roti_canai | B6: Roti Canai | C6: Malaysia | D6: Starter | E6: flour | F6: butter | G6: curry_spice | H6: 10 | I6: 4 | J6: 1 | K6: =ROUND(H6*(1+Settings!$B$22*1),0) -> 12 | L6: =ROUND(H6*(1+Settings!$B$22*2),0) -> 14 | M6: =ROUND(H6*(1+Settings!$B$22*3),0) -> 16 | N6: =ROUND(H6*(1+Settings!$B$22*4),0) -> 18 | O6: =ROUND(H6*(1+Settings!$B$22*5),0) -> 20 | P6: =ROUND(H6*(1+Settings!$B$22*6),0) -> 22 | Q6: =ROUND(H6*(1+Settings!$B$22*7),0) -> 24 | R6: =ROUND(H6*(1+Settings!$B$22*8),0) -> 26 | S6: =ROUND(H6*(1+Settings!$B$22*9),0) -> 28 | T6: =H6/I6 -> 2.5 | U6: =Settings!$B$25+Settings!$B$26*1 -> 8 | V6: =Settings!$B$25+Settings!$B$26*Settings!$B$23 -> 26 | W6: =IF(COUNTIF(Ingredients!$A$5:$A$42,E6)*COUNTIF(Ingredients!$A$5:$A$42,F6)*COUNTIF(Ingredients!$A$5:$A$42,G6)>0,"OK","Missing ingredient") -> OK | Y6: Yes
A7: satay | B7: Satay | C7: Malaysia | D7: Starter | E7: chicken | F7: peanut | G7: lemongrass | H7: 14 | I7: 6 | J7: 2 | K7: =ROUND(H7*(1+Settings!$B$22*1),0) -> 17 | L7: =ROUND(H7*(1+Settings!$B$22*2),0) -> 20 | M7: =ROUND(H7*(1+Settings!$B$22*3),0) -> 22 | N7: =ROUND(H7*(1+Settings!$B$22*4),0) -> 25 | O7: =ROUND(H7*(1+Settings!$B$22*5),0) -> 28 | P7: =ROUND(H7*(1+Settings!$B$22*6),0) -> 31 | Q7: =ROUND(H7*(1+Settings!$B$22*7),0) -> 34 | R7: =ROUND(H7*(1+Settings!$B$22*8),0) -> 36 | S7: =ROUND(H7*(1+Settings!$B$22*9),0) -> 39 | T7: =H7/I7 -> 2.3333333 | U7: =Settings!$B$25+Settings!$B$26*1 -> 8 | V7: =Settings!$B$25+Settings!$B$26*Settings!$B$23 -> 26 | W7: =IF(COUNTIF(Ingredients!$A$5:$A$42,E7)*COUNTIF(Ingredients!$A$5:$A$42,F7)*COUNTIF(Ingredients!$A$5:$A$42,G7)>0,"OK","Missing ingredient") -> OK | Y7: Yes
A8: char_kway_teow | B8: Char Kway Teow | C8: Malaysia | D8: Main | E8: noodles | F8: shrimp | G8: soy_sauce | H8: 15 | I8: 6 | J8: 4 | K8: =ROUND(H8*(1+Settings!$B$22*1),0) -> 18 | L8: =ROUND(H8*(1+Settings!$B$22*2),0) -> 21 | M8: =ROUND(H8*(1+Settings!$B$22*3),0) -> 24 | N8: =ROUND(H8*(1+Settings!$B$22*4),0) -> 27 | O8: =ROUND(H8*(1+Settings!$B$22*5),0) -> 30 | P8: =ROUND(H8*(1+Settings!$B$22*6),0) -> 33 | Q8: =ROUND(H8*(1+Settings!$B$22*7),0) -> 36 | R8: =ROUND(H8*(1+Settings!$B$22*8),0) -> 39 | S8: =ROUND(H8*(1+Settings!$B$22*9),0) -> 42 | T8: =H8/I8 -> 2.5 | U8: =Settings!$B$25+Settings!$B$26*1 -> 8 | V8: =Settings!$B$25+Settings!$B$26*Settings!$B$23 -> 26 | W8: =IF(COUNTIF(Ingredients!$A$5:$A$42,E8)*COUNTIF(Ingredients!$A$5:$A$42,F8)*COUNTIF(Ingredients!$A$5:$A$42,G8)>0,"OK","Missing ingredient") -> OK | Y8: Yes
A9: teh_tarik | B9: Teh Tarik | C9: Malaysia | D9: Drink | E9: tea | F9: milk | G9: sugar | H9: 8 | I9: 3 | J9: 15 | K9: =ROUND(H9*(1+Settings!$B$22*1),0) -> 10 | L9: =ROUND(H9*(1+Settings!$B$22*2),0) -> 11 | M9: =ROUND(H9*(1+Settings!$B$22*3),0) -> 13 | N9: =ROUND(H9*(1+Settings!$B$22*4),0) -> 14 | O9: =ROUND(H9*(1+Settings!$B$22*5),0) -> 16 | P9: =ROUND(H9*(1+Settings!$B$22*6),0) -> 18 | Q9: =ROUND(H9*(1+Settings!$B$22*7),0) -> 19 | R9: =ROUND(H9*(1+Settings!$B$22*8),0) -> 21 | S9: =ROUND(H9*(1+Settings!$B$22*9),0) -> 22 | T9: =H9/I9 -> 2.6666667 | U9: =Settings!$B$25+Settings!$B$26*1 -> 8 | V9: =Settings!$B$25+Settings!$B$26*Settings!$B$23 -> 26 | W9: =IF(COUNTIF(Ingredients!$A$5:$A$42,E9)*COUNTIF(Ingredients!$A$5:$A$42,F9)*COUNTIF(Ingredients!$A$5:$A$42,G9)>0,"OK","Missing ingredient") -> OK | Y9: No
A10: shoyu_ramen | B10: Shoyu Ramen | C10: Japan | D10: Main | E10: noodles | F10: egg | G10: soy_sauce | H10: 16 | I10: 6 | J10: 2 | K10: =ROUND(H10*(1+Settings!$B$22*1),0) -> 19 | L10: =ROUND(H10*(1+Settings!$B$22*2),0) -> 22 | M10: =ROUND(H10*(1+Settings!$B$22*3),0) -> 26 | N10: =ROUND(H10*(1+Settings!$B$22*4),0) -> 29 | O10: =ROUND(H10*(1+Settings!$B$22*5),0) -> 32 | P10: =ROUND(H10*(1+Settings!$B$22*6),0) -> 35 | Q10: =ROUND(H10*(1+Settings!$B$22*7),0) -> 38 | R10: =ROUND(H10*(1+Settings!$B$22*8),0) -> 42 | S10: =ROUND(H10*(1+Settings!$B$22*9),0) -> 45 | T10: =H10/I10 -> 2.6666667 | U10: =Settings!$B$25+Settings!$B$26*1 -> 8 | V10: =Settings!$B$25+Settings!$B$26*Settings!$B$23 -> 26 | W10: =IF(COUNTIF(Ingredients!$A$5:$A$42,E10)*COUNTIF(Ingredients!$A$5:$A$42,F10)*COUNTIF(Ingredients!$A$5:$A$42,G10)>0,"OK","Missing ingredient") -> OK | X10: Prototype price and cook time | Y10: No
A11: sushi | B11: Sushi | C11: Japan | D11: Starter | E11: rice | F11: fish | G11: seaweed | H11: 18 | I11: 7 | J11: 3 | K11: =ROUND(H11*(1+Settings!$B$22*1),0) -> 22 | L11: =ROUND(H11*(1+Settings!$B$22*2),0) -> 25 | M11: =ROUND(H11*(1+Settings!$B$22*3),0) -> 29 | N11: =ROUND(H11*(1+Settings!$B$22*4),0) -> 32 | O11: =ROUND(H11*(1+Settings!$B$22*5),0) -> 36 | P11: =ROUND(H11*(1+Settings!$B$22*6),0) -> 40 | Q11: =ROUND(H11*(1+Settings!$B$22*7),0) -> 43 | R11: =ROUND(H11*(1+Settings!$B$22*8),0) -> 47 | S11: =ROUND(H11*(1+Settings!$B$22*9),0) -> 50 | T11: =H11/I11 -> 2.5714286 | U11: =Settings!$B$25+Settings!$B$26*1 -> 8 | V11: =Settings!$B$25+Settings!$B$26*Settings!$B$23 -> 26 | W11: =IF(COUNTIF(Ingredients!$A$5:$A$42,E11)*COUNTIF(Ingredients!$A$5:$A$42,F11)*COUNTIF(Ingredients!$A$5:$A$42,G11)>0,"OK","Missing ingredient") -> OK | Y11: No
A12: tempura | B12: Tempura | C12: Japan | D12: Starter | E12: shrimp | F12: flour | G12: egg | H12: 17 | I12: 6 | J12: 5 | K12: =ROUND(H12*(1+Settings!$B$22*1),0) -> 20 | L12: =ROUND(H12*(1+Settings!$B$22*2),0) -> 24 | M12: =ROUND(H12*(1+Settings!$B$22*3),0) -> 27 | N12: =ROUND(H12*(1+Settings!$B$22*4),0) -> 31 | O12: =ROUND(H12*(1+Settings!$B$22*5),0) -> 34 | P12: =ROUND(H12*(1+Settings!$B$22*6),0) -> 37 | Q12: =ROUND(H12*(1+Settings!$B$22*7),0) -> 41 | R12: =ROUND(H12*(1+Settings!$B$22*8),0) -> 44 | S12: =ROUND(H12*(1+Settings!$B$22*9),0) -> 48 | T12: =H12/I12 -> 2.8333333 | U12: =Settings!$B$25+Settings!$B$26*1 -> 8 | V12: =Settings!$B$25+Settings!$B$26*Settings!$B$23 -> 26 | W12: =IF(COUNTIF(Ingredients!$A$5:$A$42,E12)*COUNTIF(Ingredients!$A$5:$A$42,F12)*COUNTIF(Ingredients!$A$5:$A$42,G12)>0,"OK","Missing ingredient") -> OK | Y12: No
A13: matcha_parfait | B13: Matcha Parfait | C13: Japan | D13: Dessert | E13: matcha | F13: milk | G13: sugar | H13: 13 | I13: 4 | J13: 6 | K13: =ROUND(H13*(1+Settings!$B$22*1),0) -> 16 | L13: =ROUND(H13*(1+Settings!$B$22*2),0) -> 18 | M13: =ROUND(H13*(1+Settings!$B$22*3),0) -> 21 | N13: =ROUND(H13*(1+Settings!$B$22*4),0) -> 23 | O13: =ROUND(H13*(1+Settings!$B$22*5),0) -> 26 | P13: =ROUND(H13*(1+Settings!$B$22*6),0) -> 29 | Q13: =ROUND(H13*(1+Settings!$B$22*7),0) -> 31 | R13: =ROUND(H13*(1+Settings!$B$22*8),0) -> 34 | S13: =ROUND(H13*(1+Settings!$B$22*9),0) -> 36 | T13: =H13/I13 -> 3.25 | U13: =Settings!$B$25+Settings!$B$26*1 -> 8 | V13: =Settings!$B$25+Settings!$B$26*Settings!$B$23 -> 26 | W13: =IF(COUNTIF(Ingredients!$A$5:$A$42,E13)*COUNTIF(Ingredients!$A$5:$A$42,F13)*COUNTIF(Ingredients!$A$5:$A$42,G13)>0,"OK","Missing ingredient") -> OK | Y13: No
A14: matcha_latte | B14: Iced Matcha Latte | C14: Japan | D14: Drink | E14: matcha | F14: milk | G14: ice | H14: 10 | I14: 3 | J14: 16 | K14: =ROUND(H14*(1+Settings!$B$22*1),0) -> 12 | L14: =ROUND(H14*(1+Settings!$B$22*2),0) -> 14 | M14: =ROUND(H14*(1+Settings!$B$22*3),0) -> 16 | N14: =ROUND(H14*(1+Settings!$B$22*4),0) -> 18 | O14: =ROUND(H14*(1+Settings!$B$22*5),0) -> 20 | P14: =ROUND(H14*(1+Settings!$B$22*6),0) -> 22 | Q14: =ROUND(H14*(1+Settings!$B$22*7),0) -> 24 | R14: =ROUND(H14*(1+Settings!$B$22*8),0) -> 26 | S14: =ROUND(H14*(1+Settings!$B$22*9),0) -> 28 | T14: =H14/I14 -> 3.3333333 | U14: =Settings!$B$25+Settings!$B$26*1 -> 8 | V14: =Settings!$B$25+Settings!$B$26*Settings!$B$23 -> 26 | W14: =IF(COUNTIF(Ingredients!$A$5:$A$42,E14)*COUNTIF(Ingredients!$A$5:$A$42,F14)*COUNTIF(Ingredients!$A$5:$A$42,G14)>0,"OK","Missing ingredient") -> OK | Y14: No
A15: bibimbap | B15: Bibimbap | C15: Korea | D15: Main | E15: rice | F15: egg | G15: gochujang | H15: 16 | I15: 6 | J15: 3 | K15: =ROUND(H15*(1+Settings!$B$22*1),0) -> 19 | L15: =ROUND(H15*(1+Settings!$B$22*2),0) -> 22 | M15: =ROUND(H15*(1+Settings!$B$22*3),0) -> 26 | N15: =ROUND(H15*(1+Settings!$B$22*4),0) -> 29 | O15: =ROUND(H15*(1+Settings!$B$22*5),0) -> 32 | P15: =ROUND(H15*(1+Settings!$B$22*6),0) -> 35 | Q15: =ROUND(H15*(1+Settings!$B$22*7),0) -> 38 | R15: =ROUND(H15*(1+Settings!$B$22*8),0) -> 42 | S15: =ROUND(H15*(1+Settings!$B$22*9),0) -> 45 | T15: =H15/I15 -> 2.6666667 | U15: =Settings!$B$25+Settings!$B$26*1 -> 8 | V15: =Settings!$B$25+Settings!$B$26*Settings!$B$23 -> 26 | W15: =IF(COUNTIF(Ingredients!$A$5:$A$42,E15)*COUNTIF(Ingredients!$A$5:$A$42,F15)*COUNTIF(Ingredients!$A$5:$A$42,G15)>0,"OK","Missing ingredient") -> OK | Y15: No
A16: tteokbokki | B16: Tteokbokki | C16: Korea | D16: Starter | E16: rice_cake | F16: gochujang | G16: sugar | H16: 13 | I16: 5 | J16: 4 | K16: =ROUND(H16*(1+Settings!$B$22*1),0) -> 16 | L16: =ROUND(H16*(1+Settings!$B$22*2),0) -> 18 | M16: =ROUND(H16*(1+Settings!$B$22*3),0) -> 21 | N16: =ROUND(H16*(1+Settings!$B$22*4),0) -> 23 | O16: =ROUND(H16*(1+Settings!$B$22*5),0) -> 26 | P16: =ROUND(H16*(1+Settings!$B$22*6),0) -> 29 | Q16: =ROUND(H16*(1+Settings!$B$22*7),0) -> 31 | R16: =ROUND(H16*(1+Settings!$B$22*8),0) -> 34 | S16: =ROUND(H16*(1+Settings!$B$22*9),0) -> 36 | T16: =H16/I16 -> 2.6 | U16: =Settings!$B$25+Settings!$B$26*1 -> 8 | V16: =Settings!$B$25+Settings!$B$26*Settings!$B$23 -> 26 | W16: =IF(COUNTIF(Ingredients!$A$5:$A$42,E16)*COUNTIF(Ingredients!$A$5:$A$42,F16)*COUNTIF(Ingredients!$A$5:$A$42,G16)>0,"OK","Missing ingredient") -> OK | Y16: No
A17: korean_fried_chicken | B17: Korean Fried Chicken | C17: Korea | D17: Main | E17: chicken | F17: flour | G17: garlic | H17: 19 | I17: 7 | J17: 7 | K17: =ROUND(H17*(1+Settings!$B$22*1),0) -> 23 | L17: =ROUND(H17*(1+Settings!$B$22*2),0) -> 27 | M17: =ROUND(H17*(1+Settings!$B$22*3),0) -> 30 | N17: =ROUND(H17*(1+Settings!$B$22*4),0) -> 34 | O17: =ROUND(H17*(1+Settings!$B$22*5),0) -> 38 | P17: =ROUND(H17*(1+Settings!$B$22*6),0) -> 42 | Q17: =ROUND(H17*(1+Settings!$B$22*7),0) -> 46 | R17: =ROUND(H17*(1+Settings!$B$22*8),0) -> 49 | S17: =ROUND(H17*(1+Settings!$B$22*9),0) -> 53 | T17: =H17/I17 -> 2.7142857 | U17: =Settings!$B$25+Settings!$B$26*1 -> 8 | V17: =Settings!$B$25+Settings!$B$26*Settings!$B$23 -> 26 | W17: =IF(COUNTIF(Ingredients!$A$5:$A$42,E17)*COUNTIF(Ingredients!$A$5:$A$42,F17)*COUNTIF(Ingredients!$A$5:$A$42,G17)>0,"OK","Missing ingredient") -> OK | Y17: No
A18: kimchi_jjigae | B18: Kimchi Jjigae | C18: Korea | D18: Main | E18: cabbage | F18: tofu | G18: chili | H18: 15 | I18: 6 | J18: 8 | K18: =ROUND(H18*(1+Settings!$B$22*1),0) -> 18 | L18: =ROUND(H18*(1+Settings!$B$22*2),0) -> 21 | M18: =ROUND(H18*(1+Settings!$B$22*3),0) -> 24 | N18: =ROUND(H18*(1+Settings!$B$22*4),0) -> 27 | O18: =ROUND(H18*(1+Settings!$B$22*5),0) -> 30 | P18: =ROUND(H18*(1+Settings!$B$22*6),0) -> 33 | Q18: =ROUND(H18*(1+Settings!$B$22*7),0) -> 36 | R18: =ROUND(H18*(1+Settings!$B$22*8),0) -> 39 | S18: =ROUND(H18*(1+Settings!$B$22*9),0) -> 42 | T18: =H18/I18 -> 2.5 | U18: =Settings!$B$25+Settings!$B$26*1 -> 8 | V18: =Settings!$B$25+Settings!$B$26*Settings!$B$23 -> 26 | W18: =IF(COUNTIF(Ingredients!$A$5:$A$42,E18)*COUNTIF(Ingredients!$A$5:$A$42,F18)*COUNTIF(Ingredients!$A$5:$A$42,G18)>0,"OK","Missing ingredient") -> OK | Y18: No
A19: banana_milk | B19: Banana Milk | C19: Korea | D19: Drink | E19: banana | F19: milk | G19: sugar | H19: 9 | I19: 3 | J19: 17 | K19: =ROUND(H19*(1+Settings!$B$22*1),0) -> 11 | L19: =ROUND(H19*(1+Settings!$B$22*2),0) -> 13 | M19: =ROUND(H19*(1+Settings!$B$22*3),0) -> 14 | N19: =ROUND(H19*(1+Settings!$B$22*4),0) -> 16 | O19: =ROUND(H19*(1+Settings!$B$22*5),0) -> 18 | P19: =ROUND(H19*(1+Settings!$B$22*6),0) -> 20 | Q19: =ROUND(H19*(1+Settings!$B$22*7),0) -> 22 | R19: =ROUND(H19*(1+Settings!$B$22*8),0) -> 23 | S19: =ROUND(H19*(1+Settings!$B$22*9),0) -> 25 | T19: =H19/I19 -> 3 | U19: =Settings!$B$25+Settings!$B$26*1 -> 8 | V19: =Settings!$B$25+Settings!$B$26*Settings!$B$23 -> 26 | W19: =IF(COUNTIF(Ingredients!$A$5:$A$42,E19)*COUNTIF(Ingredients!$A$5:$A$42,F19)*COUNTIF(Ingredients!$A$5:$A$42,G19)>0,"OK","Missing ingredient") -> OK | Y19: No
A20: margherita | B20: Margherita Pizza | C20: Italy | D20: Main | E20: flour | F20: tomato | G20: cheese | H20: 18 | I20: 7 | J20: 1 | K20: =ROUND(H20*(1+Settings!$B$22*1),0) -> 22 | L20: =ROUND(H20*(1+Settings!$B$22*2),0) -> 25 | M20: =ROUND(H20*(1+Settings!$B$22*3),0) -> 29 | N20: =ROUND(H20*(1+Settings!$B$22*4),0) -> 32 | O20: =ROUND(H20*(1+Settings!$B$22*5),0) -> 36 | P20: =ROUND(H20*(1+Settings!$B$22*6),0) -> 40 | Q20: =ROUND(H20*(1+Settings!$B$22*7),0) -> 43 | R20: =ROUND(H20*(1+Settings!$B$22*8),0) -> 47 | S20: =ROUND(H20*(1+Settings!$B$22*9),0) -> 50 | T20: =H20/I20 -> 2.5714286 | U20: =Settings!$B$25+Settings!$B$26*1 -> 8 | V20: =Settings!$B$25+Settings!$B$26*Settings!$B$23 -> 26 | W20: =IF(COUNTIF(Ingredients!$A$5:$A$42,E20)*COUNTIF(Ingredients!$A$5:$A$42,F20)*COUNTIF(Ingredients!$A$5:$A$42,G20)>0,"OK","Missing ingredient") -> OK | X20: Prototype price and cook time | Y20: Yes
A21: carbonara | B21: Carbonara | C21: Italy | D21: Main | E21: pasta | F21: egg | G21: cheese | H21: 17 | I21: 6 | J21: 5 | K21: =ROUND(H21*(1+Settings!$B$22*1),0) -> 20 | L21: =ROUND(H21*(1+Settings!$B$22*2),0) -> 24 | M21: =ROUND(H21*(1+Settings!$B$22*3),0) -> 27 | N21: =ROUND(H21*(1+Settings!$B$22*4),0) -> 31 | O21: =ROUND(H21*(1+Settings!$B$22*5),0) -> 34 | P21: =ROUND(H21*(1+Settings!$B$22*6),0) -> 37 | Q21: =ROUND(H21*(1+Settings!$B$22*7),0) -> 41 | R21: =ROUND(H21*(1+Settings!$B$22*8),0) -> 44 | S21: =ROUND(H21*(1+Settings!$B$22*9),0) -> 48 | T21: =H21/I21 -> 2.8333333 | U21: =Settings!$B$25+Settings!$B$26*1 -> 8 | V21: =Settings!$B$25+Settings!$B$26*Settings!$B$23 -> 26 | W21: =IF(COUNTIF(Ingredients!$A$5:$A$42,E21)*COUNTIF(Ingredients!$A$5:$A$42,F21)*COUNTIF(Ingredients!$A$5:$A$42,G21)>0,"OK","Missing ingredient") -> OK | X21: Halal-friendly version (no pork) | Y21: No
A22: mushroom_risotto | B22: Mushroom Risotto | C22: Italy | D22: Main | E22: rice | F22: mushroom | G22: butter | H22: 19 | I22: 8 | J22: 9 | K22: =ROUND(H22*(1+Settings!$B$22*1),0) -> 23 | L22: =ROUND(H22*(1+Settings!$B$22*2),0) -> 27 | M22: =ROUND(H22*(1+Settings!$B$22*3),0) -> 30 | N22: =ROUND(H22*(1+Settings!$B$22*4),0) -> 34 | O22: =ROUND(H22*(1+Settings!$B$22*5),0) -> 38 | P22: =ROUND(H22*(1+Settings!$B$22*6),0) -> 42 | Q22: =ROUND(H22*(1+Settings!$B$22*7),0) -> 46 | R22: =ROUND(H22*(1+Settings!$B$22*8),0) -> 49 | S22: =ROUND(H22*(1+Settings!$B$22*9),0) -> 53 | T22: =H22/I22 -> 2.375 | U22: =Settings!$B$25+Settings!$B$26*1 -> 8 | V22: =Settings!$B$25+Settings!$B$26*Settings!$B$23 -> 26 | W22: =IF(COUNTIF(Ingredients!$A$5:$A$42,E22)*COUNTIF(Ingredients!$A$5:$A$42,F22)*COUNTIF(Ingredients!$A$5:$A$42,G22)>0,"OK","Missing ingredient") -> OK | Y22: No
A23: tiramisu | B23: Tiramisu | C23: Italy | D23: Dessert | E23: coffee | F23: cream | G23: sugar | H23: 16 | I23: 5 | J23: 10 | K23: =ROUND(H23*(1+Settings!$B$22*1),0) -> 19 | L23: =ROUND(H23*(1+Settings!$B$22*2),0) -> 22 | M23: =ROUND(H23*(1+Settings!$B$22*3),0) -> 26 | N23: =ROUND(H23*(1+Settings!$B$22*4),0) -> 29 | O23: =ROUND(H23*(1+Settings!$B$22*5),0) -> 32 | P23: =ROUND(H23*(1+Settings!$B$22*6),0) -> 35 | Q23: =ROUND(H23*(1+Settings!$B$22*7),0) -> 38 | R23: =ROUND(H23*(1+Settings!$B$22*8),0) -> 42 | S23: =ROUND(H23*(1+Settings!$B$22*9),0) -> 45 | T23: =H23/I23 -> 3.2 | U23: =Settings!$B$25+Settings!$B$26*1 -> 8 | V23: =Settings!$B$25+Settings!$B$26*Settings!$B$23 -> 26 | W23: =IF(COUNTIF(Ingredients!$A$5:$A$42,E23)*COUNTIF(Ingredients!$A$5:$A$42,F23)*COUNTIF(Ingredients!$A$5:$A$42,G23)>0,"OK","Missing ingredient") -> OK | Y23: No
A24: limonata | B24: Limonata | C24: Italy | D24: Drink | E24: lemon | F24: sugar | G24: ice | H24: 9 | I24: 3 | J24: 18 | K24: =ROUND(H24*(1+Settings!$B$22*1),0) -> 11 | L24: =ROUND(H24*(1+Settings!$B$22*2),0) -> 13 | M24: =ROUND(H24*(1+Settings!$B$22*3),0) -> 14 | N24: =ROUND(H24*(1+Settings!$B$22*4),0) -> 16 | O24: =ROUND(H24*(1+Settings!$B$22*5),0) -> 18 | P24: =ROUND(H24*(1+Settings!$B$22*6),0) -> 20 | Q24: =ROUND(H24*(1+Settings!$B$22*7),0) -> 22 | R24: =ROUND(H24*(1+Settings!$B$22*8),0) -> 23 | S24: =ROUND(H24*(1+Settings!$B$22*9),0) -> 25 | T24: =H24/I24 -> 3 | U24: =Settings!$B$25+Settings!$B$26*1 -> 8 | V24: =Settings!$B$25+Settings!$B$26*Settings!$B$23 -> 26 | W24: =IF(COUNTIF(Ingredients!$A$5:$A$42,E24)*COUNTIF(Ingredients!$A$5:$A$42,F24)*COUNTIF(Ingredients!$A$5:$A$42,G24)>0,"OK","Missing ingredient") -> OK | Y24: No
A25: cheeseburger | B25: Cheeseburger | C25: USA | D25: Main | E25: beef | F25: cheese | G25: bun | H25: 15 | I25: 6 | J25: 1 | K25: =ROUND(H25*(1+Settings!$B$22*1),0) -> 18 | L25: =ROUND(H25*(1+Settings!$B$22*2),0) -> 21 | M25: =ROUND(H25*(1+Settings!$B$22*3),0) -> 24 | N25: =ROUND(H25*(1+Settings!$B$22*4),0) -> 27 | O25: =ROUND(H25*(1+Settings!$B$22*5),0) -> 30 | P25: =ROUND(H25*(1+Settings!$B$22*6),0) -> 33 | Q25: =ROUND(H25*(1+Settings!$B$22*7),0) -> 36 | R25: =ROUND(H25*(1+Settings!$B$22*8),0) -> 39 | S25: =ROUND(H25*(1+Settings!$B$22*9),0) -> 42 | T25: =H25/I25 -> 2.5 | U25: =Settings!$B$25+Settings!$B$26*1 -> 8 | V25: =Settings!$B$25+Settings!$B$26*Settings!$B$23 -> 26 | W25: =IF(COUNTIF(Ingredients!$A$5:$A$42,E25)*COUNTIF(Ingredients!$A$5:$A$42,F25)*COUNTIF(Ingredients!$A$5:$A$42,G25)>0,"OK","Missing ingredient") -> OK | X25: Prototype price and cook time | Y25: Yes
A26: mac_and_cheese | B26: Mac and Cheese | C26: USA | D26: Main | E26: pasta | F26: cheese | G26: milk | H26: 12 | I26: 5 | J26: 2 | K26: =ROUND(H26*(1+Settings!$B$22*1),0) -> 14 | L26: =ROUND(H26*(1+Settings!$B$22*2),0) -> 17 | M26: =ROUND(H26*(1+Settings!$B$22*3),0) -> 19 | N26: =ROUND(H26*(1+Settings!$B$22*4),0) -> 22 | O26: =ROUND(H26*(1+Settings!$B$22*5),0) -> 24 | P26: =ROUND(H26*(1+Settings!$B$22*6),0) -> 26 | Q26: =ROUND(H26*(1+Settings!$B$22*7),0) -> 29 | R26: =ROUND(H26*(1+Settings!$B$22*8),0) -> 31 | S26: =ROUND(H26*(1+Settings!$B$22*9),0) -> 34 | T26: =H26/I26 -> 2.4 | U26: =Settings!$B$25+Settings!$B$26*1 -> 8 | V26: =Settings!$B$25+Settings!$B$26*Settings!$B$23 -> 26 | W26: =IF(COUNTIF(Ingredients!$A$5:$A$42,E26)*COUNTIF(Ingredients!$A$5:$A$42,F26)*COUNTIF(Ingredients!$A$5:$A$42,G26)>0,"OK","Missing ingredient") -> OK | Y26: No
A27: pancakes | B27: Pancakes | C27: USA | D27: Dessert | E27: flour | F27: egg | G27: milk | H27: 11 | I27: 4 | J27: 1 | K27: =ROUND(H27*(1+Settings!$B$22*1),0) -> 13 | L27: =ROUND(H27*(1+Settings!$B$22*2),0) -> 15 | M27: =ROUND(H27*(1+Settings!$B$22*3),0) -> 18 | N27: =ROUND(H27*(1+Settings!$B$22*4),0) -> 20 | O27: =ROUND(H27*(1+Settings!$B$22*5),0) -> 22 | P27: =ROUND(H27*(1+Settings!$B$22*6),0) -> 24 | Q27: =ROUND(H27*(1+Settings!$B$22*7),0) -> 26 | R27: =ROUND(H27*(1+Settings!$B$22*8),0) -> 29 | S27: =ROUND(H27*(1+Settings!$B$22*9),0) -> 31 | T27: =H27/I27 -> 2.75 | U27: =Settings!$B$25+Settings!$B$26*1 -> 8 | V27: =Settings!$B$25+Settings!$B$26*Settings!$B$23 -> 26 | W27: =IF(COUNTIF(Ingredients!$A$5:$A$42,E27)*COUNTIF(Ingredients!$A$5:$A$42,F27)*COUNTIF(Ingredients!$A$5:$A$42,G27)>0,"OK","Missing ingredient") -> OK | X27: Level 1 dessert, so all 3 starting categories have a dish | Y27: Yes
A28: hot_dog | B28: Hot Dog | C28: USA | D28: Starter | E28: sausage | F28: bun | G28: onion | H28: 12 | I28: 4 | J28: 6 | K28: =ROUND(H28*(1+Settings!$B$22*1),0) -> 14 | L28: =ROUND(H28*(1+Settings!$B$22*2),0) -> 17 | M28: =ROUND(H28*(1+Settings!$B$22*3),0) -> 19 | N28: =ROUND(H28*(1+Settings!$B$22*4),0) -> 22 | O28: =ROUND(H28*(1+Settings!$B$22*5),0) -> 24 | P28: =ROUND(H28*(1+Settings!$B$22*6),0) -> 26 | Q28: =ROUND(H28*(1+Settings!$B$22*7),0) -> 29 | R28: =ROUND(H28*(1+Settings!$B$22*8),0) -> 31 | S28: =ROUND(H28*(1+Settings!$B$22*9),0) -> 34 | T28: =H28/I28 -> 3 | U28: =Settings!$B$25+Settings!$B$26*1 -> 8 | V28: =Settings!$B$25+Settings!$B$26*Settings!$B$23 -> 26 | W28: =IF(COUNTIF(Ingredients!$A$5:$A$42,E28)*COUNTIF(Ingredients!$A$5:$A$42,F28)*COUNTIF(Ingredients!$A$5:$A$42,G28)>0,"OK","Missing ingredient") -> OK | X28: Chicken sausage, halal-friendly | Y28: No
A29: strawberry_shake | B29: Strawberry Milkshake | C29: USA | D29: Drink | E29: strawberry | F29: milk | G29: ice | H29: 10 | I29: 3 | J29: 20 | K29: =ROUND(H29*(1+Settings!$B$22*1),0) -> 12 | L29: =ROUND(H29*(1+Settings!$B$22*2),0) -> 14 | M29: =ROUND(H29*(1+Settings!$B$22*3),0) -> 16 | N29: =ROUND(H29*(1+Settings!$B$22*4),0) -> 18 | O29: =ROUND(H29*(1+Settings!$B$22*5),0) -> 20 | P29: =ROUND(H29*(1+Settings!$B$22*6),0) -> 22 | Q29: =ROUND(H29*(1+Settings!$B$22*7),0) -> 24 | R29: =ROUND(H29*(1+Settings!$B$22*8),0) -> 26 | S29: =ROUND(H29*(1+Settings!$B$22*9),0) -> 28 | T29: =H29/I29 -> 3.3333333 | U29: =Settings!$B$25+Settings!$B$26*1 -> 8 | V29: =Settings!$B$25+Settings!$B$26*Settings!$B$23 -> 26 | W29: =IF(COUNTIF(Ingredients!$A$5:$A$42,E29)*COUNTIF(Ingredients!$A$5:$A$42,F29)*COUNTIF(Ingredients!$A$5:$A$42,G29)>0,"OK","Missing ingredient") -> OK | Y29: No
A31: Each ingredient needed to take one dish to max level | H31: =Settings!$B$24*(Settings!$B$23-1) -> 9 | I31: of each of its 3 ingredients
A32: Average base price, level 1 dishes | H32: =AVERAGEIF(J5:J29,1,H5:H29) -> 13.2
A33: XP for upgrading a dish to level N = base + per level x N (see Settings).

Sheet Furniture
A1: Furniture, decor and floors
A2: 38 items, including Restaurant City's toilets, drinks counter and fun machines. About 120 are planned for launch.
A4: ID | B4: Item | C4: Category | D4: Cost (coins) | E4: Ambience points | F4: Unlocks at level | G4: Sell-back (coins) | H4: Coins per ambience point | I4: Source | J4: Notes | K4: Themed set | L4: In Phase 1
A5: table | B5: Table and chair | C5: Function | D5: 80 | E5: 0 | F5: 1 | G5: =ROUND(D5*Settings!$B$100,0) -> 27 | H5: =IF(E5>0,D5/E5,"-") -> - | I5: Prototype | J5: Seats one guest | L5: Yes
A6: round_table | B6: Round marble table | C6: Function | D6: 120 | E6: 1 | F6: 3 | G6: =ROUND(D6*Settings!$B$100,0) -> 40 | H6: =IF(E6>0,D6/E6,"-") -> 120 | I6: New proposal | J6: Kopitiam style; seats one guest | L6: Yes
A7: stove | B7: Stove | C7: Function | D7: 200 | E7: 0 | F7: 1 | G7: =ROUND(D7*Settings!$B$100,0) -> 67 | H7: =IF(E7>0,D7/E7,"-") -> - | I7: Prototype | J7: One chef cooks here | L7: Yes
A8: serving_counter | B8: Serving counter | C8: Function | D8: 150 | E8: 0 | F8: 2 | G8: =ROUND(D8*Settings!$B$100,0) -> 50 | H8: =IF(E8>0,D8/E8,"-") -> - | I8: New proposal | J8: Finished dishes wait here | L8: Yes
A9: wok_burner | B9: Wok burner | C9: Function | D9: 280 | E9: 0 | F9: 5 | G9: =ROUND(D9*Settings!$B$100,0) -> 93 | H9: =IF(E9>0,D9/E9,"-") -> - | I9: New proposal | J9: A faster stove | L9: Yes
A10: booth | B10: Booth seat | C10: Function | D10: 180 | E10: 1 | F10: 7 | G10: =ROUND(D10*Settings!$B$100,0) -> 60 | H10: =IF(E10>0,D10/E10,"-") -> 180 | I10: New proposal | J10: Seats one guest | L10: Yes
A11: toilet | B11: Toilet | C11: Function | D11: 150 | E11: 0 | F11: 8 | G11: =ROUND(D11*Settings!$B$100,0) -> 50 | H11: =IF(E11>0,D11/E11,"-") -> - | I11: Restaurant City feature | J11: Needed from level 8; cleaners keep it clean | L11: No
A12: drinks_counter | B12: Drinks counter | C12: Function | D12: 350 | E12: 0 | F12: 15 | G12: =ROUND(D12*Settings!$B$100,0) -> 117 | H12: =IF(E12>0,D12/E12,"-") -> - | I12: Restaurant City feature | J12: Needed to serve drinks | L12: No
A13: jukebox | B13: Jukebox | C13: Fun | D13: 250 | E13: 2 | F13: 4 | G13: =ROUND(D13*Settings!$B$100,0) -> 83 | H13: =IF(E13>0,D13/E13,"-") -> 125 | I13: Restaurant City feature | J13: Earns coins; needs repair | L13: No
A14: arcade | B14: Arcade machine | C14: Fun | D14: 300 | E14: 2 | F14: 7 | G14: =ROUND(D14*Settings!$B$100,0) -> 100 | H14: =IF(E14>0,D14/E14,"-") -> 150 | I14: Restaurant City feature | J14: Entertains waiting guests; earns coins; needs repair | L14: No
A15: potted_palm | B15: Potted palm | C15: Decor | D15: 40 | E15: 1 | F15: 1 | G15: =ROUND(D15*Settings!$B$100,0) -> 13 | H15: =IF(E15>0,D15/E15,"-") -> 40 | I15: Prototype | L15: Yes
A16: wall_clock | B16: Wall clock | C16: Decor | D16: 50 | E16: 1 | F16: 1 | G16: =ROUND(D16*Settings!$B$100,0) -> 17 | H16: =IF(E16>0,D16/E16,"-") -> 50 | I16: New proposal | L16: Yes
A17: lantern | B17: Lantern | C17: Decor | D17: 90 | E17: 2 | F17: 2 | G17: =ROUND(D17*Settings!$B$100,0) -> 30 | H17: =IF(E17>0,D17/E17,"-") -> 45 | I17: Prototype | L17: Yes
A18: chalkboard_menu | B18: Chalkboard menu | C18: Decor | D18: 70 | E18: 1 | F18: 2 | G18: =ROUND(D18*Settings!$B$100,0) -> 23 | H18: =IF(E18>0,D18/E18,"-") -> 70 | I18: New proposal | L18: Yes
A19: flower_vase | B19: Flower vase | C19: Decor | D19: 60 | E19: 1 | F19: 3 | G19: =ROUND(D19*Settings!$B$100,0) -> 20 | H19: =IF(E19>0,D19/E19,"-") -> 60 | I19: New proposal | L19: Yes
A20: ceiling_fan | B20: Ceiling fan | C20: Decor | D20: 120 | E20: 2 | F20: 4 | G20: =ROUND(D20*Settings!$B$100,0) -> 40 | H20: =IF(E20>0,D20/E20,"-") -> 60 | I20: New proposal | L20: Yes
A21: fountain | B21: Fountain | C21: Decor | D21: 300 | E21: 5 | F21: 4 | G21: =ROUND(D21*Settings!$B$100,0) -> 100 | H21: =IF(E21>0,D21/E21,"-") -> 60 | I21: Prototype | L21: Yes
A22: woven_rug | B22: Woven rug | C22: Decor | D22: 100 | E22: 2 | F22: 5 | G22: =ROUND(D22*Settings!$B$100,0) -> 33 | H22: =IF(E22>0,D22/E22,"-") -> 50 | I22: New proposal | L22: Yes
A23: cookbook_shelf | B23: Cookbook shelf | C23: Decor | D23: 160 | E23: 3 | F23: 6 | G23: =ROUND(D23*Settings!$B$100,0) -> 53 | H23: =IF(E23>0,D23/E23,"-") -> 53.333333 | I23: New proposal | L23: Yes
A24: koi_pond | B24: Koi pond | C24: Decor | D24: 450 | E24: 7 | F24: 8 | G24: =ROUND(D24*Settings!$B$100,0) -> 150 | H24: =IF(E24>0,D24/E24,"-") -> 64.285714 | I24: New proposal | L24: Yes
A25: kopitiam_poster | B25: Vintage kopitiam poster | C25: Decor | D25: 70 | E25: 1 | F25: 2 | G25: =ROUND(D25*Settings!$B$100,0) -> 23 | H25: =IF(E25>0,D25/E25,"-") -> 70 | I25: New proposal | K25: Malaysia | L25: Yes
A26: bunga_raya_planter | B26: Bunga raya planter | C26: Decor | D26: 80 | E26: 2 | F26: 2 | G26: =ROUND(D26*Settings!$B$100,0) -> 27 | H26: =IF(E26>0,D26/E26,"-") -> 40 | I26: New proposal | K26: Malaysia | L26: Yes
A27: batik_wall_art | B27: Batik wall hanging | C27: Decor | D27: 110 | E27: 2 | F27: 3 | G27: =ROUND(D27*Settings!$B$100,0) -> 37 | H27: =IF(E27>0,D27/E27,"-") -> 55 | I27: New proposal | K27: Malaysia | L27: Yes
A28: songket_runner | B28: Songket table runner | C28: Decor | D28: 90 | E28: 2 | F28: 3 | G28: =ROUND(D28*Settings!$B$100,0) -> 30 | H28: =IF(E28>0,D28/E28,"-") -> 45 | I28: New proposal | K28: Malaysia | L28: Yes
A29: wau_kite | B29: Wau kite wall piece | C29: Decor | D29: 130 | E29: 2 | F29: 4 | G29: =ROUND(D29*Settings!$B$100,0) -> 43 | H29: =IF(E29>0,D29/E29,"-") -> 65 | I29: New proposal | K29: Malaysia | L29: Yes
A30: rattan_lamp | B30: Rattan lamp | C30: Decor | D30: 120 | E30: 2 | F30: 4 | G30: =ROUND(D30*Settings!$B$100,0) -> 40 | H30: =IF(E30>0,D30/E30,"-") -> 60 | I30: New proposal | K30: Malaysia | L30: Yes
A31: hawker_sign | B31: Hawker stall sign | C31: Decor | D31: 150 | E31: 3 | F31: 5 | G31: =ROUND(D31*Settings!$B$100,0) -> 50 | H31: =IF(E31>0,D31/E31,"-") -> 50 | I31: New proposal | K31: Malaysia | L31: Yes
A32: tiffin_stand | B32: Tiffin carrier stand | C32: Decor | D32: 100 | E32: 2 | F32: 5 | G32: =ROUND(D32*Settings!$B$100,0) -> 33 | H32: =IF(E32>0,D32/E32,"-") -> 50 | I32: New proposal | K32: Malaysia | L32: Yes
A33: kuih_display | B33: Kuih display case | C33: Decor | D33: 200 | E33: 3 | F33: 6 | G33: =ROUND(D33*Settings!$B$100,0) -> 67 | H33: =IF(E33>0,D33/E33,"-") -> 66.666667 | I33: New proposal | K33: Malaysia | L33: Yes
A34: peranakan_screen | B34: Peranakan tile screen | C34: Decor | D34: 240 | E34: 4 | F34: 7 | G34: =ROUND(D34*Settings!$B$100,0) -> 80 | H34: =IF(E34>0,D34/E34,"-") -> 60 | I34: New proposal | K34: Malaysia | L34: Yes
A35: floor_mint | B35: Mint tile floor | C35: Floor | D35: 0 | E35: 0 | F35: 1 | G35: =ROUND(D35*Settings!$B$100,0) -> 0 | H35: =IF(E35>0,D35/E35,"-") -> - | I35: Prototype | J35: Default floor | L35: Yes
A36: floor_oak | B36: Oak plank floor | C36: Floor | D36: 120 | E36: 0 | F36: 1 | G36: =ROUND(D36*Settings!$B$100,0) -> 40 | H36: =IF(E36>0,D36/E36,"-") -> - | I36: Prototype | L36: Yes
A37: floor_terrazzo | B37: Terrazzo floor | C37: Floor | D37: 220 | E37: 0 | F37: 1 | G37: =ROUND(D37*Settings!$B$100,0) -> 73 | H37: =IF(E37>0,D37/E37,"-") -> - | I37: Prototype | L37: Yes
A38: floor_sunset | B38: Sunset tile floor | C38: Floor | D38: 260 | E38: 0 | F38: 1 | G38: =ROUND(D38*Settings!$B$100,0) -> 87 | H38: =IF(E38>0,D38/E38,"-") -> - | I38: Prototype | L38: Yes
A39: wall_cream | B39: Cream plaster wall | C39: Wallpaper | D39: 0 | E39: 0 | F39: 1 | G39: =ROUND(D39*Settings!$B$100,0) -> 0 | H39: =IF(E39>0,D39/E39,"-") -> - | I39: New proposal | J39: Default wall | L39: Yes
A40: wall_sky | B40: Sky blue wall | C40: Wallpaper | D40: 100 | E40: 0 | F40: 1 | G40: =ROUND(D40*Settings!$B$100,0) -> 33 | H40: =IF(E40>0,D40/E40,"-") -> - | I40: New proposal | L40: Yes
A41: wall_bamboo | B41: Bamboo panel wall | C41: Wallpaper | D41: 140 | E41: 0 | F41: 2 | G41: =ROUND(D41*Settings!$B$100,0) -> 47 | H41: =IF(E41>0,D41/E41,"-") -> - | I41: New proposal | L41: Yes
...

Sheet Expansions
A1: Restaurant expansions
A2: Indoor space grows with level, and outdoor terraces open from level 20, as in Restaurant City. Our costs use our own coin scale.
A4: ID | B4: Expansion | C4: Type | D4: Size (tiles) | E4: Unlocks at level | F4: Cost (coins) | G4: Restaurant City did | H4: In Phase 1
A5: indoor_1 | B5: First expansion | C5: Indoor | D5: 10 x 12 | E5: 6 | F5: 1500 | G5: The room grew from 7 x 7 as you levelled | H5: =IF(E5<=Settings!$B$102,"Yes","No") -> Yes
A6: indoor_2 | B6: Second expansion | C6: Indoor | D6: 12 x 14 | E6: 12 | F6: 4000 | H6: =IF(E6<=Settings!$B$102,"Yes","No") -> No
A7: indoor_3 | B7: Third expansion | C7: Indoor | D7: 14 x 16 | E7: 18 | F7: 9000 | H7: =IF(E7<=Settings!$B$102,"Yes","No") -> No
A8: terrace_1 | B8: Outdoor terrace | C8: Terrace | D8: 6 x 6 | E8: 20 | F8: 12000 | G8: 6 x 6 at level 20 for 5,000 coins | H8: =IF(E8<=Settings!$B$102,"Yes","No") -> No
A9: terrace_2 | B9: Terrace upgrade | C9: Terrace | D9: 8 x 8 | E9: 25 | F9: 25000 | G9: 8 x 8 at level 25 for 15,000 | H9: =IF(E9<=Settings!$B$102,"Yes","No") -> No
A10: terrace_3 | B10: Terrace upgrade | C10: Terrace | D10: 10 x 10 | E10: 30 | F10: 45000 | G10: 10 x 10 at level 30 for 32,000 | H10: =IF(E10<=Settings!$B$102,"Yes","No") -> No
A11: terrace_4 | B11: Terrace upgrade | C11: Terrace | D11: 12 x 12 | E11: 35 | F11: 80000 | G11: 12 x 12 at level 35 for 70,000 | H11: =IF(E11<=Settings!$B$102,"Yes","No") -> No
A12: terrace_5 | B12: Terrace upgrade | C12: Terrace | D12: 14 x 14 | E12: 40 | F12: 140000 | G12: 14 x 14 at level 40 for 150,000 | H12: =IF(E12<=Settings!$B$102,"Yes","No") -> No
A13: terrace_6 | B13: Terrace upgrade | C13: Terrace | D13: 16 x 16 | E13: 45 | F13: 240000 | G13: 16 x 16 at level 45 for 310,000 | H13: =IF(E13<=Settings!$B$102,"Yes","No") -> No
A14: terrace_7 | B14: Terrace upgrade | C14: Terrace | D14: 18 x 18 | E14: 50 | F14: 400000 | G14: 18 x 18 at level 50 for 550,000 | H14: =IF(E14<=Settings!$B$102,"Yes","No") -> No
A15: second_city | B15: Second restaurant in another city | C15: New restaurant | D15: 8 x 10 | E15: 30 | F15: 60000 | G15: Our upgrade: not in Restaurant City | H15: =IF(E15<=Settings!$B$102,"Yes","No") -> No

Sheet Levels
A1: Restaurant levels
A2: Levels 1 to 65, as in Restaurant City. Calculated from Settings, Dishes, Furniture and Expansions.
A4: Level | B4: XP to next level | C4: Total XP to reach | D4: Coins reward on reaching | E4: Menu categories | F4: Dishes per category | G4: Menu slots | H4: Staff slots | I4: Garden plots | J4: Dishes unlocked | K4: Items unlocked | L4: Expansions unlocked | M4: Guests to serve for next level (Lv1 dishes) | N4: In Phase 1
A5: 1 | B5: =Settings!$B$11+Settings!$B$12*A5 -> 140 | C5: 0 | D5: 0 | E5: =Settings!$B$16+(A5>=Settings!$B$17) -> 3 | F5: =Settings!$B$18+(A5>=Settings!$B$19)+(A5>=Settings!$B$20) -> 1 | G5: =E5*F5 -> 3 | H5: =Settings!$B$47+COUNTIF(Settings!$B$48:$B$53,"<="&A5) -> 3 | I5: =COUNTIF(Settings!$B$83:$B$91,"<="&A5) -> 0 | J5: =COUNTIF(Dishes!$J$5:$J$29,A5) -> 5 | K5: =COUNTIF(Furniture!$F$5:$F$42,A5) -> 10 | L5: =COUNTIF(Expansions!$E$5:$E$15,A5) -> 0 | M5: =ROUNDUP(B5/(Settings!$B$25+Settings!$B$26),0) -> 18 | N5: =IF(A5<=Settings!$B$102,"Yes","No") -> Yes
A6: 2 | B6: =Settings!$B$11+Settings!$B$12*A6 -> 200 | C6: =C5+B5 -> 140 | D6: =Settings!$B$14 -> 100 | E6: =Settings!$B$16+(A6>=Settings!$B$17) -> 3 | F6: =Settings!$B$18+(A6>=Settings!$B$19)+(A6>=Settings!$B$20) -> 1 | G6: =E6*F6 -> 3 | H6: =Settings!$B$47+COUNTIF(Settings!$B$48:$B$53,"<="&A6) -> 4 | I6: =COUNTIF(Settings!$B$83:$B$91,"<="&A6) -> 0 | J6: =COUNTIF(Dishes!$J$5:$J$29,A6) -> 3 | K6: =COUNTIF(Furniture!$F$5:$F$42,A6) -> 6 | L6: =COUNTIF(Expansions!$E$5:$E$15,A6) -> 0 | M6: =ROUNDUP(B6/(Settings!$B$25+Settings!$B$26),0) -> 25 | N6: =IF(A6<=Settings!$B$102,"Yes","No") -> Yes
A7: 3 | B7: =Settings!$B$11+Settings!$B$12*A7 -> 260 | C7: =C6+B6 -> 340 | D7: =Settings!$B$14 -> 100 | E7: =Settings!$B$16+(A7>=Settings!$B$17) -> 3 | F7: =Settings!$B$18+(A7>=Settings!$B$19)+(A7>=Settings!$B$20) -> 1 | G7: =E7*F7 -> 3 | H7: =Settings!$B$47+COUNTIF(Settings!$B$48:$B$53,"<="&A7) -> 4 | I7: =COUNTIF(Settings!$B$83:$B$91,"<="&A7) -> 1 | J7: =COUNTIF(Dishes!$J$5:$J$29,A7) -> 2 | K7: =COUNTIF(Furniture!$F$5:$F$42,A7) -> 5 | L7: =COUNTIF(Expansions!$E$5:$E$15,A7) -> 0 | M7: =ROUNDUP(B7/(Settings!$B$25+Settings!$B$26),0) -> 33 | N7: =IF(A7<=Settings!$B$102,"Yes","No") -> Yes
A8: 4 | B8: =Settings!$B$11+Settings!$B$12*A8 -> 320 | C8: =C7+B7 -> 600 | D8: =Settings!$B$14 -> 100 | E8: =Settings!$B$16+(A8>=Settings!$B$17) -> 3 | F8: =Settings!$B$18+(A8>=Settings!$B$19)+(A8>=Settings!$B$20) -> 1 | G8: =E8*F8 -> 3 | H8: =Settings!$B$47+COUNTIF(Settings!$B$48:$B$53,"<="&A8) -> 4 | I8: =COUNTIF(Settings!$B$83:$B$91,"<="&A8) -> 1 | J8: =COUNTIF(Dishes!$J$5:$J$29,A8) -> 2 | K8: =COUNTIF(Furniture!$F$5:$F$42,A8) -> 5 | L8: =COUNTIF(Expansions!$E$5:$E$15,A8) -> 0 | M8: =ROUNDUP(B8/(Settings!$B$25+Settings!$B$26),0) -> 40 | N8: =IF(A8<=Settings!$B$102,"Yes","No") -> Yes
A9: 5 | B9: =Settings!$B$11+Settings!$B$12*A9 -> 380 | C9: =C8+B8 -> 920 | D9: =Settings!$B$14 -> 100 | E9: =Settings!$B$16+(A9>=Settings!$B$17) -> 3 | F9: =Settings!$B$18+(A9>=Settings!$B$19)+(A9>=Settings!$B$20) -> 1 | G9: =E9*F9 -> 3 | H9: =Settings!$B$47+COUNTIF(Settings!$B$48:$B$53,"<="&A9) -> 5 | I9: =COUNTIF(Settings!$B$83:$B$91,"<="&A9) -> 1 | J9: =COUNTIF(Dishes!$J$5:$J$29,A9) -> 2 | K9: =COUNTIF(Furniture!$F$5:$F$42,A9) -> 4 | L9: =COUNTIF(Expansions!$E$5:$E$15,A9) -> 0 | M9: =ROUNDUP(B9/(Settings!$B$25+Settings!$B$26),0) -> 48 | N9: =IF(A9<=Settings!$B$102,"Yes","No") -> Yes
A10: 6 | B10: =Settings!$B$11+Settings!$B$12*A10 -> 440 | C10: =C9+B9 -> 1300 | D10: =Settings!$B$14 -> 100 | E10: =Settings!$B$16+(A10>=Settings!$B$17) -> 3 | F10: =Settings!$B$18+(A10>=Settings!$B$19)+(A10>=Settings!$B$20) -> 1 | G10: =E10*F10 -> 3 | H10: =Settings!$B$47+COUNTIF(Settings!$B$48:$B$53,"<="&A10) -> 5 | I10: =COUNTIF(Settings!$B$83:$B$91,"<="&A10) -> 2 | J10: =COUNTIF(Dishes!$J$5:$J$29,A10) -> 2 | K10: =COUNTIF(Furniture!$F$5:$F$42,A10) -> 2 | L10: =COUNTIF(Expansions!$E$5:$E$15,A10) -> 1 | M10: =ROUNDUP(B10/(Settings!$B$25+Settings!$B$26),0) -> 55 | N10: =IF(A10<=Settings!$B$102,"Yes","No") -> Yes
A11: 7 | B11: =Settings!$B$11+Settings!$B$12*A11 -> 500 | C11: =C10+B10 -> 1740 | D11: =Settings!$B$14 -> 100 | E11: =Settings!$B$16+(A11>=Settings!$B$17) -> 3 | F11: =Settings!$B$18+(A11>=Settings!$B$19)+(A11>=Settings!$B$20) -> 1 | G11: =E11*F11 -> 3 | H11: =Settings!$B$47+COUNTIF(Settings!$B$48:$B$53,"<="&A11) -> 5 | I11: =COUNTIF(Settings!$B$83:$B$91,"<="&A11) -> 2 | J11: =COUNTIF(Dishes!$J$5:$J$29,A11) -> 1 | K11: =COUNTIF(Furniture!$F$5:$F$42,A11) -> 3 | L11: =COUNTIF(Expansions!$E$5:$E$15,A11) -> 0 | M11: =ROUNDUP(B11/(Settings!$B$25+Settings!$B$26),0) -> 63 | N11: =IF(A11<=Settings!$B$102,"Yes","No") -> Yes
A12: 8 | B12: =Settings!$B$11+Settings!$B$12*A12 -> 560 | C12: =C11+B11 -> 2240 | D12: =Settings!$B$14 -> 100 | E12: =Settings!$B$16+(A12>=Settings!$B$17) -> 3 | F12: =Settings!$B$18+(A12>=Settings!$B$19)+(A12>=Settings!$B$20) -> 1 | G12: =E12*F12 -> 3 | H12: =Settings!$B$47+COUNTIF(Settings!$B$48:$B$53,"<="&A12) -> 5 | I12: =COUNTIF(Settings!$B$83:$B$91,"<="&A12) -> 2 | J12: =COUNTIF(Dishes!$J$5:$J$29,A12) -> 1 | K12: =COUNTIF(Furniture!$F$5:$F$42,A12) -> 2 | L12: =COUNTIF(Expansions!$E$5:$E$15,A12) -> 0 | M12: =ROUNDUP(B12/(Settings!$B$25+Settings!$B$26),0) -> 70 | N12: =IF(A12<=Settings!$B$102,"Yes","No") -> Yes
A13: 9 | B13: =Settings!$B$11+Settings!$B$12*A13 -> 620 | C13: =C12+B12 -> 2800 | D13: =Settings!$B$14 -> 100 | E13: =Settings!$B$16+(A13>=Settings!$B$17) -> 3 | F13: =Settings!$B$18+(A13>=Settings!$B$19)+(A13>=Settings!$B$20) -> 1 | G13: =E13*F13 -> 3 | H13: =Settings!$B$47+COUNTIF(Settings!$B$48:$B$53,"<="&A13) -> 5 | I13: =COUNTIF(Settings!$B$83:$B$91,"<="&A13) -> 3 | J13: =COUNTIF(Dishes!$J$5:$J$29,A13) -> 1 | K13: =COUNTIF(Furniture!$F$5:$F$42,A13) -> 0 | L13: =COUNTIF(Expansions!$E$5:$E$15,A13) -> 0 | M13: =ROUNDUP(B13/(Settings!$B$25+Settings!$B$26),0) -> 78 | N13: =IF(A13<=Settings!$B$102,"Yes","No") -> Yes
A14: 10 | B14: =Settings!$B$11+Settings!$B$12*A14 -> 680 | C14: =C13+B13 -> 3420 | D14: =Settings!$B$14 -> 100 | E14: =Settings!$B$16+(A14>=Settings!$B$17) -> 3 | F14: =Settings!$B$18+(A14>=Settings!$B$19)+(A14>=Settings!$B$20) -> 2 | G14: =E14*F14 -> 6 | H14: =Settings!$B$47+COUNTIF(Settings!$B$48:$B$53,"<="&A14) -> 5 | I14: =COUNTIF(Settings!$B$83:$B$91,"<="&A14) -> 3 | J14: =COUNTIF(Dishes!$J$5:$J$29,A14) -> 1 | K14: =COUNTIF(Furniture!$F$5:$F$42,A14) -> 0 | L14: =COUNTIF(Expansions!$E$5:$E$15,A14) -> 0 | M14: =ROUNDUP(B14/(Settings!$B$25+Settings!$B$26),0) -> 85 | N14: =IF(A14<=Settings!$B$102,"Yes","No") -> Yes
A15: 11 | B15: =Settings!$B$11+Settings!$B$12*A15 -> 740 | C15: =C14+B14 -> 4100 | D15: =Settings!$B$14 -> 100 | E15: =Settings!$B$16+(A15>=Settings!$B$17) -> 3 | F15: =Settings!$B$18+(A15>=Settings!$B$19)+(A15>=Settings!$B$20) -> 2 | G15: =E15*F15 -> 6 | H15: =Settings!$B$47+COUNTIF(Settings!$B$48:$B$53,"<="&A15) -> 6 | I15: =COUNTIF(Settings!$B$83:$B$91,"<="&A15) -> 3 | J15: =COUNTIF(Dishes!$J$5:$J$29,A15) -> 0 | K15: =COUNTIF(Furniture!$F$5:$F$42,A15) -> 0 | L15: =COUNTIF(Expansions!$E$5:$E$15,A15) -> 0 | M15: =ROUNDUP(B15/(Settings!$B$25+Settings!$B$26),0) -> 93 | N15: =IF(A15<=Settings!$B$102,"Yes","No") -> No
A16: 12 | B16: =Settings!$B$11+Settings!$B$12*A16 -> 800 | C16: =C15+B15 -> 4840 | D16: =Settings!$B$14 -> 100 | E16: =Settings!$B$16+(A16>=Settings!$B$17) -> 3 | F16: =Settings!$B$18+(A16>=Settings!$B$19)+(A16>=Settings!$B$20) -> 2 | G16: =E16*F16 -> 6 | H16: =Settings!$B$47+COUNTIF(Settings!$B$48:$B$53,"<="&A16) -> 6 | I16: =COUNTIF(Settings!$B$83:$B$91,"<="&A16) -> 3 | J16: =COUNTIF(Dishes!$J$5:$J$29,A16) -> 0 | K16: =COUNTIF(Furniture!$F$5:$F$42,A16) -> 0 | L16: =COUNTIF(Expansions!$E$5:$E$15,A16) -> 1 | M16: =ROUNDUP(B16/(Settings!$B$25+Settings!$B$26),0) -> 100 | N16: =IF(A16<=Settings!$B$102,"Yes","No") -> No
A17: 13 | B17: =Settings!$B$11+Settings!$B$12*A17 -> 860 | C17: =C16+B16 -> 5640 | D17: =Settings!$B$14 -> 100 | E17: =Settings!$B$16+(A17>=Settings!$B$17) -> 3 | F17: =Settings!$B$18+(A17>=Settings!$B$19)+(A17>=Settings!$B$20) -> 2 | G17: =E17*F17 -> 6 | H17: =Settings!$B$47+COUNTIF(Settings!$B$48:$B$53,"<="&A17) -> 6 | I17: =COUNTIF(Settings!$B$83:$B$91,"<="&A17) -> 4 | J17: =COUNTIF(Dishes!$J$5:$J$29,A17) -> 0 | K17: =COUNTIF(Furniture!$F$5:$F$42,A17) -> 0 | L17: =COUNTIF(Expansions!$E$5:$E$15,A17) -> 0 | M17: =ROUNDUP(B17/(Settings!$B$25+Settings!$B$26),0) -> 108 | N17: =IF(A17<=Settings!$B$102,"Yes","No") -> No
... A69: 65 | B69: =Settings!$B$11+Settings!$B$12*A69 -> 3980 | C69: =C68+B68 -> 129920 | D69: =Settings!$B$14 -> 100 | E69: =Settings!$B$16+(A69>=Settings!$B$17) -> 4 | F69: =Settings!$B$18+(A69>=Settings!$B$19)+(A69>=Settings!$B$20) -> 3 | G69: =E69*F69 -> 12 | H69: =Settings!$B$47+COUNTIF(Settings!$B$48:$B$53,"<="&A69) -> 9 | I69: =COUNTIF(Settings!$B$83:$B$91,"<="&A69) -> 9 | J69: =COUNTIF(Dishes!$J$5:$J$29,A69) -> 0 | K69: =COUNTIF(Furniture!$F$5:$F$42,A69) -> 0 | L69: =COUNTIF(Expansions!$E$5:$E$15,A69) -> 0 | M69: =ROUNDUP(B69/(Settings!$B$25+Settings!$B$26),0) -> 498 | N69: =IF(A69<=Settings!$B$102,"Yes","No") -> No

Sheet Staff
A1: Staff
